Workbook

Sheet Cards
A1: ID | B1: Name | C1: Set Code | D1: Set Number | E1: Set Name | F1: Category | G1: Type Line | H1: Archetype | I1: Added | J1: Image | K1: Coded | L1: Tested | M1: Confirmed | N1: Ready For Omega | O1: Notes
A2: CARD-0001 | B2: STARDRAKE OF GRAVITIC COILS | C2: TATA | D2: 001 | E2: Tainted Tails | F2: Monster | G2: Machine / Effect / Xyz | H2: Stardrake | I2: 2025-01-17 | J2: /assets/cards/STARDRAKE-OF-GRAVITIC-COILS.jpg | K2: No | L2: No | M2: No | N2: =IF(AND($K2="Yes",$L2="Yes",$M2="Yes"),"Yes","No")
A3: CARD-0002 | B3: REACTOR SHOCKER | C3: TATA | D3: 002 | E3: Tainted Tails | F3: Spell | G3: Spell / Quick-Play | H3: Reactor | I3: 2025-01-17 | J3: /assets/cards/REACTOR-SHOCKER.jpg | K3: No | L3: No | M3: No | N3: =IF(AND($K3="Yes",$L3="Yes",$M3="Yes"),"Yes","No")
A4: CARD-0003 | B4: THE CONDESCENDER | C4: TATA | D4: 003 | E4: Tainted Tails | F4: Monster | G4: Fiend / Effect | H4: Condescender | I4: 2025-01-17 | J4: /assets/cards/THE-CONDESCENDER.jpg | K4: No | L4: No | M4: No | N4: =IF(AND($K4="Yes",$L4="Yes",$M4="Yes"),"Yes","No")
A5: CARD-0004 | B5: STAINED BIRD BRIA | C5: TATA | D5: 004 | E5: Tainted Tails | F5: Monster | G5: Winged Beast / Effect | H5: Stain | I5: 2025-01-17 | J5: /assets/cards/STAINED-BIRD-BRIA.jpg | K5: No | L5: No | M5: No | N5: =IF(AND($K5="Yes",$L5="Yes",$M5="Yes"),"Yes","No")
A6: CARD-0005 | B6: STAINED DEER DANTE | C6: TATA | D6: 005 | E6: Tainted Tails | F6: Monster | G6: Beast / Effect | H6: Stain | I6: 2025-01-17 | J6: /assets/cards/STAINED-DEER-DANTE.jpg | K6: No | L6: No | M6: No | N6: =IF(AND($K6="Yes",$L6="Yes",$M6="Yes"),"Yes","No")
A7: CARD-0006 | B7: STAINED FOX FENESS | C7: TATA | D7: 006 | E7: Tainted Tails | F7: Monster | G7: Aqua / Effect | H7: Stain | I7: 2025-01-17 | J7: /assets/cards/STAINED-FOX-FENESS.jpg | K7: No | L7: No | M7: No | N7: =IF(AND($K7="Yes",$L7="Yes",$M7="Yes"),"Yes","No")
A8: CARD-0007 | B8: STAINED RAPTOR ROLLO | C8: TATA | D8: 007 | E8: Tainted Tails | F8: Monster | G8: Reptile / Effect | H8: Stain | I8: 2025-01-17 | J8: /assets/cards/STAINED-RAPTOR-ROLLO.jpg | K8: No | L8: No | M8: No | N8: =IF(AND($K8="Yes",$L8="Yes",$M8="Yes"),"Yes","No")
A9: CARD-0008 | B9: STAINED SOLITAIRE | C9: TATA | D9: 008 | E9: Tainted Tails | F9: Monster | G9: Warrior / Effect | H9: Stain | I9: 2025-01-17 | J9: /assets/cards/STAINED-SOLITAIRE.jpg | K9: No | L9: No | M9: No | N9: =IF(AND($K9="Yes",$L9="Yes",$M9="Yes"),"Yes","No")
A10: CARD-0009 | B10: STARGAZER OF THE STAINED | C10: TATA | D10: 009 | E10: Tainted Tails | F10: Monster | G10: Warrior / Effect | H10: Stain | I10: 2025-01-17 | J10: /assets/cards/STARGAZER-OF-THE-STAINED.jpg | K10: No | L10: No | M10: No | N10: =IF(AND($K10="Yes",$L10="Yes",$M10="Yes"),"Yes","No")
A11: CARD-0010 | B11: STAINED SCIONESS SILIA | C11: TATA | D11: 010 | E11: Tainted Tails | F11: Monster | G11: Fairy / Effect | H11: Stain | I11: 2025-01-17 | J11: /assets/cards/STAINED-SCIONESS-SILIA.jpg | K11: No | L11: No | M11: No | N11: =IF(AND($K11="Yes",$L11="Yes",$M11="Yes"),"Yes","No")
A12: CARD-0011 | B12: STAINED SOVEREIGN SILAS | C12: TATA | D12: 011 | E12: Tainted Tails | F12: Monster | G12: Spellcaster / Effect | H12: Stain | I12: 2025-01-17 | J12: /assets/cards/STAINED-SOVEREIGN-SILAS.jpg | K12: No | L12: No | M12: No | N12: =IF(AND($K12="Yes",$L12="Yes",$M12="Yes"),"Yes","No")
A13: CARD-0012 | B13: STAINED SILHOUETTE | C13: TATA | D13: 012 | E13: Tainted Tails | F13: Monster | G13: Illusion / Effect | H13: Stain | I13: 2025-01-17 | J13: /assets/cards/STAINED-SILHOUETTE.jpg | K13: No | L13: No | M13: No | N13: =IF(AND($K13="Yes",$L13="Yes",$M13="Yes"),"Yes","No")
... A81: CARD-0080 | B81: Tove in the Wild | C81: TATA | D81: 080 | E81: Tainted Tails | F81: Monster | G81: Beast / Fusion / Effect | H81: Domestica | I81: 2025-01-17 | J81: /assets/cards/TOVE-IN-THE-WILD.jpg | K81: No | L81: No | M81: No | N81: =IF(AND($K81="Yes",$L81="Yes",$M81="Yes"),"Yes","No")
A82: CARD-0081 | B82: Remembrance of the Melody | C82: COOR | D82: 0001 | E82: Cosmic Origins | F82: Spell | G82: Spell / Quick-Play | I82: 2025-05-01 | J82: /assets/cards/REMEMBRANCE-OF-THE-MELODY.jpeg | K82: No | L82: No | M82: No | N82: =IF(AND($K82="Yes",$L82="Yes",$M82="Yes"),"Yes","No")
A83: CARD-0082 | B83: Chaos Fusion | C83: COOR | D83: 0002 | E83: Cosmic Origins | F83: Spell | G83: Spell / Quick-Play | H83: Chaos | I83: 2025-05-01 | J83: /assets/cards/CHAOS-FUSION.jpeg | K83: No | L83: No | M83: No | N83: =IF(AND($K83="Yes",$L83="Yes",$M83="Yes"),"Yes","No")
A84: CARD-0083 | B84: URSARCTIC MIKAILUS | C84: COOR | D84: 003 | E84: Cosmic Origins | F84: Monster | G84: Beast / Effect | H84: Ursarctic | I84: 2025-05-01 | J84: /assets/cards/URSARCTIC-MIKAILUS.jpg | K84: No | L84: No | M84: No | N84: =IF(AND($K84="Yes",$L84="Yes",$M84="Yes"),"Yes","No")
A85: CARD-0084 | B85: URSARCTIC MEGAILUS | C85: COOR | D85: 004 | E85: Cosmic Origins | F85: Monster | G85: Beast-Warrior / Effect | H85: Ursarctic | I85: 2025-05-01 | J85: /assets/cards/URSARCTIC-MEGAILUS.jpg | K85: No | L85: No | M85: No | N85: =IF(AND($K85="Yes",$L85="Yes",$M85="Yes"),"Yes","No")
A86: CARD-0085 | B86: URSARCTIC LEOSHIP | C86: COOR | D86: 005 | E86: Cosmic Origins | F86: Spell | G86: Spell / Continuous | H86: Ursarctic | I86: 2025-05-01 | J86: /assets/cards/URSARCTIC-LEOSHIP.jpg | K86: No | L86: No | M86: No | N86: =IF(AND($K86="Yes",$L86="Yes",$M86="Yes"),"Yes","No")
A87: CARD-0086 | B87: URSARCTIC OCTANTIS | C87: COOR | D87: 006 | E87: Cosmic Origins | F87: Monster | G87: Machine / Effect / Synchro | H87: Ursarctic | I87: 2025-05-01 | J87: /assets/cards/URSARCTIC-OCTANTIS.jpg | K87: No | L87: No | M87: No | N87: =IF(AND($K87="Yes",$L87="Yes",$M87="Yes"),"Yes","No")
A88: CARD-0087 | B88: URSARCTIC HEXTANIUS | C88: COOR | D88: 007 | E88: Cosmic Origins | F88: Monster | G88: Beast-Warrior / Effect / Synchro / Tuner | H88: Ursarctic | I88: 2025-05-01 | J88: /assets/cards/URSARCTIC-HEXTANIUS.jpg | K88: No | L88: No | M88: No | N88: =IF(AND($K88="Yes",$L88="Yes",$M88="Yes"),"Yes","No")
A89: CARD-0088 | B89: URSARCTIC NORDBAR | C89: COOR | D89: 008 | E89: Cosmic Origins | F89: Monster | G89: Beast-Warrior / Effect / Synchro | H89: Ursarctic | I89: 2025-05-01 | J89: /assets/cards/URSARCTIC-NORDBAR.jpg | K89: No | L89: No | M89: No | N89: =IF(AND($K89="Yes",$L89="Yes",$M89="Yes"),"Yes","No")
A90: CARD-0089 | B90: Carina of the Eldoran System | C90: COOR | D90: 009 | E90: Cosmic Origins | F90: Monster | G90: Warrior / Normal | H90: Galactica | I90: 2025-05-01 | J90: /assets/cards/Carina-of-the-eldoran-system.jpeg | K90: No | L90: No | M90: No | N90: =IF(AND($K90="Yes",$L90="Yes",$M90="Yes"),"Yes","No")
A91: CARD-0090 | B91: Branching to Guidance | C91: COOR | D91: 0010 | E91: Cosmic Origins | F91: Spell | G91: Spell / Normal | I91: 2025-05-01 | J91: /assets/cards/BRANCHING-TO-GUIDANCE.jpeg | K91: No | L91: No | M91: No | N91: =IF(AND($K91="Yes",$L91="Yes",$M91="Yes"),"Yes","No")
A92: CARD-0092 | B92: Rigel the Thousand-Armed | C92: COOR | D92: 0012 | E92: Cosmic Origins | F92: Monster | G92: Cyberse / Effect / Link | I92: 2025-05-01 | J92: /assets/cards/RIGEL-THE-THOUSAND-ARMED.jpeg | K92: No | L92: No | M92: No | N92: =IF(AND($K92="Yes",$L92="Yes",$M92="Yes"),"Yes","No")
A93: CARD-0093 | B93: Prophecy of Infernos | C93: COOR | D93: 0013 | E93: Cosmic Origins | F93: Monster | G93: Spellcaster / Effect | H93: Prophecy | I93: 2025-05-01 | J93: /assets/cards/PROPHECY-OF-INFERNOS.jpeg | K93: No | L93: No | M93: No | N93: =IF(AND($K93="Yes",$L93="Yes",$M93="Yes"),"Yes","No")
A94: CARD-0094 | B94: Prophecy of Waterfalls | C94: COOR | D94: 0014 | E94: Cosmic Origins | F94: Monster | G94: Spellcaster / Effect | H94: Prophecy | I94: 2025-05-01 | J94: /assets/cards/PROPHECY-OF-WATERFALLS.jpeg | K94: No | L94: No | M94: No | N94: =IF(AND($K94="Yes",$L94="Yes",$M94="Yes"),"Yes","No")
A95: CARD-0095 | B95: Prophecy of Boulders | C95: COOR | D95: 0015 | E95: Cosmic Origins | F95: Monster | G95: Spellcaster / Effect | H95: Prophecy | I95: 2025-05-01 | J95: /assets/cards/PROPHECY-OF-BOULDERS.jpeg | K95: No | L95: No | M95: No | N95: =IF(AND($K95="Yes",$L95="Yes",$M95="Yes"),"Yes","No")
A96: CARD-0096 | B96: Prophecy of Storms | C96: COOR | D96: 0016 | E96: Cosmic Origins | F96: Monster | G96: Spellcaster / Effect | H96: Prophecy | I96: 2025-05-01 | J96: /assets/cards/PROPHECY-OF-STORMS.jpeg | K96: No | L96: No | M96: No | N96: =IF(AND($K96="Yes",$L96="Yes",$M96="Yes"),"Yes","No")
A97: CARD-0097 | B97: Prophecy of Rays | C97: COOR | D97: 0017 | E97: Cosmic Origins | F97: Monster | G97: Spellcaster / Effect | H97: Prophecy | I97: 2025-05-01 | J97: /assets/cards/PROPHECY-OF-RAYS.jpeg | K97: No | L97: No | M97: No | N97: =IF(AND($K97="Yes",$L97="Yes",$M97="Yes"),"Yes","No")
A98: CARD-0098 | B98: Prophecy of Shadows | C98: COOR | D98: 0018 | E98: Cosmic Origins | F98: Monster | G98: Spellcaster / Effect | H98: Prophecy | I98: 2025-05-01 | J98: /assets/cards/PROPHECY-OF-SHADOWS.jpeg | K98: No | L98: No | M98: No | N98: =IF(AND($K98="Yes",$L98="Yes",$M98="Yes"),"Yes","No")
A99: CARD-0099 | B99: Stellaer of the Swamp | C99: COOR | D99: 019 | E99: Cosmic Origins | F99: Monster | G99: Dragon / Xyz / Effect | H99: Stellaer | I99: 2025-05-01 | J99: /assets/cards/Stellaer-of-the-Swamp.png | K99: No | L99: No | M99: No | N99: =IF(AND($K99="Yes",$L99="Yes",$M99="Yes"),"Yes","No")
A100: CARD-0100 | B100: Sustained Succubus Saria | C100: COOR | D100: 0020 | E100: Cosmic Origins | F100: Monster | G100: Zombie / Fusion / Effect | H100: Stain | I100: 2025-05-01 | J100: /assets/cards/Sustained-Succubus-Saria.jpeg | K100: No | L100: No | M100: No | N100: =IF(AND($K100="Yes",$L100="Yes",$M100="Yes"),"Yes","No")
A101: CARD-0101 | B101: A Stainless Story | C101: COOR | D101: 0021 | E101: Cosmic Origins | F101: Spell | G101: Spell / Quick-Play | H101: Stain | I101: 2025-05-01 | J101: /assets/cards/A-Stainless-Story.jpeg | K101: No | L101: No | M101: No | N101: =IF(AND($K101="Yes",$L101="Yes",$M101="Yes"),"Yes","No")
A102: CARD-0102 | B102: Mylo, the Domesticated | C102: COOR | D102: 022 | E102: Cosmic Origins | F102: Monster | G102: Beast / Effect | H102: Domestica | I102: 2025-05-01 | J102: /assets/cards/Mylo-the-Domesticated.png | K102: No | L102: No | M102: No | N102: =IF(AND($K102="Yes",$L102="Yes",$M102="Yes"),"Yes","No")
A103: CARD-0103 | B103: Nuwa, the Domesticated | C103: COOR | D103: 023 | E103: Cosmic Origins | F103: Monster | G103: Beast / Effect | H103: Domestica | I103: 2025-05-01 | J103: /assets/cards/Nuwa-the-Domesticated.png | K103: No | L103: No | M103: No | N103: =IF(AND($K103="Yes",$L103="Yes",$M103="Yes"),"Yes","No")
A104: CARD-0104 | B104: Mylo in the Wild | C104: COOR | D104: 024 | E104: Cosmic Origins | F104: Monster | G104: Beast / Fusion / Effect | H104: Domestica | I104: 2025-05-01 | J104: /assets/cards/Mylo-in-the-Wild.png | K104: No | L104: No | M104: No | N104: =IF(AND($K104="Yes",$L104="Yes",$M104="Yes"),"Yes","No")
... A112: CARD-0112 | B112: TAKAMA NO HARA | C112: COOR | D112: 032 | E112: Cosmic Origins | F112: Spell | G112: Spell / Normal | H112: Spirit | I112: 2025-05-01 | J112: /assets/cards/TAKAMA-NO-HARA.jpg | K112: No | L112: No | M112: No | N112: =IF(AND($K112="Yes",$L112="Yes",$M112="Yes"),"Yes","No")
A113: CARD-0113 | B113: Rei-Tachi Ga Kita Hi | C113: COOR | D113: 0033 | E113: Cosmic Origins | F113: Spell | G113: Spell / Continuous | I113: 2025-05-01 | J113: /assets/cards/REI---TACHI-GA-KITA-HI.jpeg | K113: No | L113: No | M113: No | N113: =IF(AND($K113="Yes",$L113="Yes",$M113="Yes"),"Yes","No")
A114: CARD-0114 | B114: OTAKEMARU THE ACCUSER | C114: COOR | D114: 034 | E114: Cosmic Origins | F114: Monster | G114: Fiend / Effect / Synchro / Spirit | H114: Spirit | I114: 2025-05-01 | J114: /assets/cards/OTAKEMARU-THE-ACCUSER.jpg | K114: No | L114: No | M114: No | N114: =IF(AND($K114="Yes",$L114="Yes",$M114="Yes"),"Yes","No")
...

Sheet Summary
A1: YGO Omega Card Checklist
A2: Generated from src/data/cards.json on 2026-04-26 02:38
A4: Total Cards | B4: =COUNTA(Cards!$A:$A)-1 | C4: =IF($B$4=0,0,B4/$B$4)
A5: Coded | B5: =COUNTIF(Cards!$K:$K,"Yes") | C5: =IF($B$4=0,0,B5/$B$4)
A6: Tested | B6: =COUNTIF(Cards!$L:$L,"Yes") | C6: =IF($B$4=0,0,B6/$B$4)
A7: Confirmed | B7: =COUNTIF(Cards!$M:$M,"Yes") | C7: =IF($B$4=0,0,B7/$B$4)
A8: Ready For Omega | B8: =COUNTIF(Cards!$N:$N,"Yes") | C8: =IF($B$4=0,0,B8/$B$4)
A11: Set Code | B11: Set Name | C11: Total | D11: Coded | E11: Tested | F11: Confirmed | G11: Ready
A12: TATA | B12: Tainted Tails | C12: =COUNTIF(Cards!$C:$C,A12) | D12: =COUNTIFS(Cards!$C:$C,A12,Cards!$K:$K,"Yes") | E12: =COUNTIFS(Cards!$C:$C,A12,Cards!$L:$L,"Yes") | F12: =COUNTIFS(Cards!$C:$C,A12,Cards!$M:$M,"Yes") | G12: =COUNTIFS(Cards!$C:$C,A12,Cards!$N:$N,"Yes")
A13: COOR | B13: Cosmic Origins | C13: =COUNTIF(Cards!$C:$C,A13) | D13: =COUNTIFS(Cards!$C:$C,A13,Cards!$K:$K,"Yes") | E13: =COUNTIFS(Cards!$C:$C,A13,Cards!$L:$L,"Yes") | F13: =COUNTIFS(Cards!$C:$C,A13,Cards!$M:$M,"Yes") | G13: =COUNTIFS(Cards!$C:$C,A13,Cards!$N:$N,"Yes")
A14: DAEL | B14: Dawn of the Elements | C14: =COUNTIF(Cards!$C:$C,A14) | D14: =COUNTIFS(Cards!$C:$C,A14,Cards!$K:$K,"Yes") | E14: =COUNTIFS(Cards!$C:$C,A14,Cards!$L:$L,"Yes") | F14: =COUNTIFS(Cards!$C:$C,A14,Cards!$M:$M,"Yes") | G14: =COUNTIFS(Cards!$C:$C,A14,Cards!$N:$N,"Yes")
B15: DAEL-0XX Dawn of the Elements | C15: =COUNTIF(Cards!$C:$C,A15) | D15: =COUNTIFS(Cards!$C:$C,A15,Cards!$K:$K,"Yes") | E15: =COUNTIFS(Cards!$C:$C,A15,Cards!$L:$L,"Yes") | F15: =COUNTIFS(Cards!$C:$C,A15,Cards!$M:$M,"Yes") | G15: =COUNTIFS(Cards!$C:$C,A15,Cards!$N:$N,"Yes")
B16: DAEL-XXX Dawn of the Elements | C16: =COUNTIF(Cards!$C:$C,A16) | D16: =COUNTIFS(Cards!$C:$C,A16,Cards!$K:$K,"Yes") | E16: =COUNTIFS(Cards!$C:$C,A16,Cards!$L:$L,"Yes") | F16: =COUNTIFS(Cards!$C:$C,A16,Cards!$M:$M,"Yes") | G16: =COUNTIFS(Cards!$C:$C,A16,Cards!$N:$N,"Yes")
A17: CHST | B17: Chronicles of the Starborn | C17: =COUNTIF(Cards!$C:$C,A17) | D17: =COUNTIFS(Cards!$C:$C,A17,Cards!$K:$K,"Yes") | E17: =COUNTIFS(Cards!$C:$C,A17,Cards!$L:$L,"Yes") | F17: =COUNTIFS(Cards!$C:$C,A17,Cards!$M:$M,"Yes") | G17: =COUNTIFS(Cards!$C:$C,A17,Cards!$N:$N,"Yes")
A18: PHPA | B18: Phantom Parade | C18: =COUNTIF(Cards!$C:$C,A18) | D18: =COUNTIFS(Cards!$C:$C,A18,Cards!$K:$K,"Yes") | E18: =COUNTIFS(Cards!$C:$C,A18,Cards!$L:$L,"Yes") | F18: =COUNTIFS(Cards!$C:$C,A18,Cards!$M:$M,"Yes") | G18: =COUNTIFS(Cards!$C:$C,A18,Cards!$N:$N,"Yes")
A19: UPST | B19: Upcoming Set | C19: =COUNTIF(Cards!$C:$C,A19) | D19: =COUNTIFS(Cards!$C:$C,A19,Cards!$K:$K,"Yes") | E19: =COUNTIFS(Cards!$C:$C,A19,Cards!$L:$L,"Yes") | F19: =COUNTIFS(Cards!$C:$C,A19,Cards!$M:$M,"Yes") | G19: =COUNTIFS(Cards!$C:$C,A19,Cards!$N:$N,"Yes")
